[2021-08-16 15:03:29,268] {taskinstance.py:896} INFO - Dependencies all met for <TaskInstance: spotify-etl.get_recently_played_songs_data 2021-08-16T15:03:27.742738+00:00 [queued]>
[2021-08-16 15:03:29,280] {taskinstance.py:896} INFO - Dependencies all met for <TaskInstance: spotify-etl.get_recently_played_songs_data 2021-08-16T15:03:27.742738+00:00 [queued]>
[2021-08-16 15:03:29,281] {taskinstance.py:1087} INFO - 
--------------------------------------------------------------------------------
[2021-08-16 15:03:29,281] {taskinstance.py:1088} INFO - Starting attempt 1 of 1
[2021-08-16 15:03:29,281] {taskinstance.py:1089} INFO - 
--------------------------------------------------------------------------------
[2021-08-16 15:03:29,300] {taskinstance.py:1107} INFO - Executing <Task(PythonOperator): get_recently_played_songs_data> on 2021-08-16T15:03:27.742738+00:00
[2021-08-16 15:03:29,305] {standard_task_runner.py:52} INFO - Started process 591 to run task
[2021-08-16 15:03:29,311] {standard_task_runner.py:76} INFO - Running: ['***', 'tasks', 'run', 'spotify-etl', 'get_recently_played_songs_data', '2021-08-16T15:03:27.742738+00:00', '--job-id', '15', '--pool', 'default_pool', '--raw', '--subdir', 'DAGS_FOLDER/spotify-etl.py', '--cfg-path', '/tmp/tmpv0amoag1', '--error-file', '/tmp/tmporrbjv24']
[2021-08-16 15:03:29,312] {standard_task_runner.py:77} INFO - Job 15: Subtask get_recently_played_songs_data
[2021-08-16 15:03:29,417] {logging_mixin.py:104} INFO - Running <TaskInstance: spotify-etl.get_recently_played_songs_data 2021-08-16T15:03:27.742738+00:00 [running]> on host 4095d62d00ed
[2021-08-16 15:03:29,484] {taskinstance.py:1302} INFO - Exporting the following env vars:
AIRFLOW_CTX_DAG_OWNER=***
AIRFLOW_CTX_DAG_ID=spotify-etl
AIRFLOW_CTX_TASK_ID=get_recently_played_songs_data
AIRFLOW_CTX_EXECUTION_DATE=2021-08-16T15:03:27.742738+00:00
AIRFLOW_CTX_DAG_RUN_ID=manual__2021-08-16T15:03:27.742738+00:00
[2021-08-16 15:03:29,853] {taskinstance.py:1501} ERROR - Task failed with exception
Traceback (most recent call last):
  File "/home/airflow/.local/lib/python3.6/site-packages/airflow/models/taskinstance.py", line 1157, in _run_raw_task
    self._prepare_and_execute_task_with_callbacks(context, task)
  File "/home/airflow/.local/lib/python3.6/site-packages/airflow/models/taskinstance.py", line 1331, in _prepare_and_execute_task_with_callbacks
    result = self._execute_task(context, task_copy)
  File "/home/airflow/.local/lib/python3.6/site-packages/airflow/models/taskinstance.py", line 1361, in _execute_task
    result = task_copy.execute(context=context)
  File "/home/airflow/.local/lib/python3.6/site-packages/airflow/operators/python.py", line 150, in execute
    return_value = self.execute_callable()
  File "/home/airflow/.local/lib/python3.6/site-packages/airflow/operators/python.py", line 161, in execute_callable
    return self.python_callable(*self.op_args, **self.op_kwargs)
  File "/opt/airflow/dags/spotify-etl.py", line 51, in get_recently_played_songs
    song_df.to_csv("data/song_df.csv")
  File "/home/airflow/.local/lib/python3.6/site-packages/pandas/core/generic.py", line 3170, in to_csv
    formatter.save()
  File "/home/airflow/.local/lib/python3.6/site-packages/pandas/io/formats/csvs.py", line 190, in save
    compression=dict(self.compression_args, method=self.compression),
  File "/home/airflow/.local/lib/python3.6/site-packages/pandas/io/common.py", line 493, in get_handle
    f = open(path_or_buf, mode, encoding=encoding, errors=errors, newline="")
FileNotFoundError: [Errno 2] No such file or directory: 'data/song_df.csv'
[2021-08-16 15:03:29,861] {taskinstance.py:1551} INFO - Marking task as FAILED. dag_id=spotify-etl, task_id=get_recently_played_songs_data, execution_date=20210816T150327, start_date=20210816T150329, end_date=20210816T150329
[2021-08-16 15:03:29,923] {local_task_job.py:149} INFO - Task exited with return code 1
