[2021-08-16 16:38:06,641] {taskinstance.py:896} INFO - Dependencies all met for <TaskInstance: spotify-etl.insert_into_database 2021-08-16T15:00:00+00:00 [queued]>
[2021-08-16 16:38:06,652] {taskinstance.py:896} INFO - Dependencies all met for <TaskInstance: spotify-etl.insert_into_database 2021-08-16T15:00:00+00:00 [queued]>
[2021-08-16 16:38:06,653] {taskinstance.py:1087} INFO - 
--------------------------------------------------------------------------------
[2021-08-16 16:38:06,653] {taskinstance.py:1088} INFO - Starting attempt 1 of 1
[2021-08-16 16:38:06,653] {taskinstance.py:1089} INFO - 
--------------------------------------------------------------------------------
[2021-08-16 16:38:06,669] {taskinstance.py:1107} INFO - Executing <Task(PythonOperator): insert_into_database> on 2021-08-16T15:00:00+00:00
[2021-08-16 16:38:06,673] {standard_task_runner.py:52} INFO - Started process 3239 to run task
[2021-08-16 16:38:06,677] {standard_task_runner.py:76} INFO - Running: ['***', 'tasks', 'run', 'spotify-etl', 'insert_into_database', '2021-08-16T15:00:00+00:00', '--job-id', '47', '--pool', 'default_pool', '--raw', '--subdir', 'DAGS_FOLDER/spotify-etl/spotify-etl.py', '--cfg-path', '/tmp/tmp9wa56_bm', '--error-file', '/tmp/tmp1zrci9nb']
[2021-08-16 16:38:06,678] {standard_task_runner.py:77} INFO - Job 47: Subtask insert_into_database
[2021-08-16 16:38:06,726] {logging_mixin.py:104} INFO - Running <TaskInstance: spotify-etl.insert_into_database 2021-08-16T15:00:00+00:00 [running]> on host 4095d62d00ed
[2021-08-16 16:38:06,782] {taskinstance.py:1302} INFO - Exporting the following env vars:
AIRFLOW_CTX_DAG_OWNER=***
AIRFLOW_CTX_DAG_ID=spotify-etl
AIRFLOW_CTX_TASK_ID=insert_into_database
AIRFLOW_CTX_EXECUTION_DATE=2021-08-16T15:00:00+00:00
AIRFLOW_CTX_DAG_RUN_ID=scheduled__2021-08-16T15:00:00+00:00
[2021-08-16 16:38:06,877] {logging_mixin.py:104} INFO - Started insertion...
[2021-08-16 16:38:06,899] {taskinstance.py:1501} ERROR - Task failed with exception
Traceback (most recent call last):
  File "/opt/airflow/dags/spotify-etl/spotify-etl.py", line 141, in insert_into_database
    cur.execute(query,tuples)
psycopg2.errors.UniqueViolation: duplicate key value violates unique constraint "primary_key_constraint"
DETAIL:  Key (played_at)=(2021-08-14T17:28:58.584Z) already exists.


During handling of the above exception, another exception occurred:

Traceback (most recent call last):
  File "/home/airflow/.local/lib/python3.6/site-packages/airflow/models/taskinstance.py", line 1157, in _run_raw_task
    self._prepare_and_execute_task_with_callbacks(context, task)
  File "/home/airflow/.local/lib/python3.6/site-packages/airflow/models/taskinstance.py", line 1331, in _prepare_and_execute_task_with_callbacks
    result = self._execute_task(context, task_copy)
  File "/home/airflow/.local/lib/python3.6/site-packages/airflow/models/taskinstance.py", line 1361, in _execute_task
    result = task_copy.execute(context=context)
  File "/home/airflow/.local/lib/python3.6/site-packages/airflow/operators/python.py", line 150, in execute
    return_value = self.execute_callable()
  File "/home/airflow/.local/lib/python3.6/site-packages/airflow/operators/python.py", line 161, in execute_callable
    return self.python_callable(*self.op_args, **self.op_kwargs)
  File "/opt/airflow/dags/spotify-etl/spotify-etl.py", line 147, in insert_into_database
    raise Exception("Error: {error}".format(error=error))
Exception: Error: duplicate key value violates unique constraint "primary_key_constraint"
DETAIL:  Key (played_at)=(2021-08-14T17:28:58.584Z) already exists.

[2021-08-16 16:38:06,907] {taskinstance.py:1551} INFO - Marking task as FAILED. dag_id=spotify-etl, task_id=insert_into_database, execution_date=20210816T150000, start_date=20210816T163806, end_date=20210816T163806
[2021-08-16 16:38:06,969] {local_task_job.py:149} INFO - Task exited with return code 1
