[2021-08-16 15:07:49,107] {taskinstance.py:896} INFO - Dependencies all met for <TaskInstance: spotify-etl.insert_into_database 2021-08-16T15:07:45.539980+00:00 [queued]>
[2021-08-16 15:07:49,118] {taskinstance.py:896} INFO - Dependencies all met for <TaskInstance: spotify-etl.insert_into_database 2021-08-16T15:07:45.539980+00:00 [queued]>
[2021-08-16 15:07:49,119] {taskinstance.py:1087} INFO - 
--------------------------------------------------------------------------------
[2021-08-16 15:07:49,120] {taskinstance.py:1088} INFO - Starting attempt 1 of 1
[2021-08-16 15:07:49,120] {taskinstance.py:1089} INFO - 
--------------------------------------------------------------------------------
[2021-08-16 15:07:49,135] {taskinstance.py:1107} INFO - Executing <Task(PythonOperator): insert_into_database> on 2021-08-16T15:07:45.539980+00:00
[2021-08-16 15:07:49,140] {standard_task_runner.py:52} INFO - Started process 957 to run task
[2021-08-16 15:07:49,143] {standard_task_runner.py:76} INFO - Running: ['***', 'tasks', 'run', 'spotify-etl', 'insert_into_database', '2021-08-16T15:07:45.539980+00:00', '--job-id', '19', '--pool', 'default_pool', '--raw', '--subdir', 'DAGS_FOLDER/spotify-etl.py', '--cfg-path', '/tmp/tmpfx7absn_', '--error-file', '/tmp/tmpt2ss5l6v']
[2021-08-16 15:07:49,144] {standard_task_runner.py:77} INFO - Job 19: Subtask insert_into_database
[2021-08-16 15:07:49,192] {logging_mixin.py:104} INFO - Running <TaskInstance: spotify-etl.insert_into_database 2021-08-16T15:07:45.539980+00:00 [running]> on host 4095d62d00ed
[2021-08-16 15:07:49,245] {taskinstance.py:1302} INFO - Exporting the following env vars:
AIRFLOW_CTX_DAG_OWNER=***
AIRFLOW_CTX_DAG_ID=spotify-etl
AIRFLOW_CTX_TASK_ID=insert_into_database
AIRFLOW_CTX_EXECUTION_DATE=2021-08-16T15:07:45.539980+00:00
AIRFLOW_CTX_DAG_RUN_ID=manual__2021-08-16T15:07:45.539980+00:00
[2021-08-16 15:07:49,247] {taskinstance.py:1501} ERROR - Task failed with exception
Traceback (most recent call last):
  File "/home/airflow/.local/lib/python3.6/site-packages/airflow/models/taskinstance.py", line 1157, in _run_raw_task
    self._prepare_and_execute_task_with_callbacks(context, task)
  File "/home/airflow/.local/lib/python3.6/site-packages/airflow/models/taskinstance.py", line 1331, in _prepare_and_execute_task_with_callbacks
    result = self._execute_task(context, task_copy)
  File "/home/airflow/.local/lib/python3.6/site-packages/airflow/models/taskinstance.py", line 1361, in _execute_task
    result = task_copy.execute(context=context)
  File "/home/airflow/.local/lib/python3.6/site-packages/airflow/operators/python.py", line 150, in execute
    return_value = self.execute_callable()
  File "/home/airflow/.local/lib/python3.6/site-packages/airflow/operators/python.py", line 161, in execute_callable
    return self.python_callable(*self.op_args, **self.op_kwargs)
  File "/opt/airflow/dags/spotify-etl.py", line 128, in insert_into_database
    song_df = pd.read_csv('song_df.csv')
  File "/home/airflow/.local/lib/python3.6/site-packages/pandas/io/parsers.py", line 688, in read_csv
    return _read(filepath_or_buffer, kwds)
  File "/home/airflow/.local/lib/python3.6/site-packages/pandas/io/parsers.py", line 454, in _read
    parser = TextFileReader(fp_or_buf, **kwds)
  File "/home/airflow/.local/lib/python3.6/site-packages/pandas/io/parsers.py", line 948, in __init__
    self._make_engine(self.engine)
  File "/home/airflow/.local/lib/python3.6/site-packages/pandas/io/parsers.py", line 1180, in _make_engine
    self._engine = CParserWrapper(self.f, **self.options)
  File "/home/airflow/.local/lib/python3.6/site-packages/pandas/io/parsers.py", line 2010, in __init__
    self._reader = parsers.TextReader(src, **kwds)
  File "pandas/_libs/parsers.pyx", line 382, in pandas._libs.parsers.TextReader.__cinit__
  File "pandas/_libs/parsers.pyx", line 674, in pandas._libs.parsers.TextReader._setup_parser_source
FileNotFoundError: [Errno 2] No such file or directory: 'song_df.csv'
[2021-08-16 15:07:49,256] {taskinstance.py:1551} INFO - Marking task as FAILED. dag_id=spotify-etl, task_id=insert_into_database, execution_date=20210816T150745, start_date=20210816T150749, end_date=20210816T150749
[2021-08-16 15:07:49,315] {local_task_job.py:149} INFO - Task exited with return code 1
