[2021-08-16 15:50:43,533] {taskinstance.py:896} INFO - Dependencies all met for <TaskInstance: spotify-etl.insert_into_database 2021-08-16T15:50:40.276899+00:00 [queued]>
[2021-08-16 15:50:43,546] {taskinstance.py:896} INFO - Dependencies all met for <TaskInstance: spotify-etl.insert_into_database 2021-08-16T15:50:40.276899+00:00 [queued]>
[2021-08-16 15:50:43,546] {taskinstance.py:1087} INFO - 
--------------------------------------------------------------------------------
[2021-08-16 15:50:43,547] {taskinstance.py:1088} INFO - Starting attempt 1 of 1
[2021-08-16 15:50:43,547] {taskinstance.py:1089} INFO - 
--------------------------------------------------------------------------------
[2021-08-16 15:50:43,565] {taskinstance.py:1107} INFO - Executing <Task(PythonOperator): insert_into_database> on 2021-08-16T15:50:40.276899+00:00
[2021-08-16 15:50:43,570] {standard_task_runner.py:52} INFO - Started process 1376 to run task
[2021-08-16 15:50:43,574] {standard_task_runner.py:76} INFO - Running: ['***', 'tasks', 'run', 'spotify-etl', 'insert_into_database', '2021-08-16T15:50:40.276899+00:00', '--job-id', '37', '--pool', 'default_pool', '--raw', '--subdir', 'DAGS_FOLDER/spotify-etl/spotify-etl.py', '--cfg-path', '/tmp/tmp0d34c6lf', '--error-file', '/tmp/tmpi6lh_arr']
[2021-08-16 15:50:43,575] {standard_task_runner.py:77} INFO - Job 37: Subtask insert_into_database
[2021-08-16 15:50:43,619] {logging_mixin.py:104} INFO - Running <TaskInstance: spotify-etl.insert_into_database 2021-08-16T15:50:40.276899+00:00 [running]> on host 4095d62d00ed
[2021-08-16 15:50:43,668] {taskinstance.py:1302} INFO - Exporting the following env vars:
AIRFLOW_CTX_DAG_OWNER=***
AIRFLOW_CTX_DAG_ID=spotify-etl
AIRFLOW_CTX_TASK_ID=insert_into_database
AIRFLOW_CTX_EXECUTION_DATE=2021-08-16T15:50:40.276899+00:00
AIRFLOW_CTX_DAG_RUN_ID=manual__2021-08-16T15:50:40.276899+00:00
[2021-08-16 15:50:43,688] {taskinstance.py:1501} ERROR - Task failed with exception
Traceback (most recent call last):
  File "/opt/airflow/dags/spotify-etl/spotify-etl.py", line 95, in get_connection
    conn = psycopg2.connect(host=params['host'],database=params['database'],user=params['user'],password=params['password'],port=params['port'])
  File "/home/airflow/.local/lib/python3.6/site-packages/psycopg2/__init__.py", line 122, in connect
    conn = _connect(dsn, connection_factory=connection_factory, **kwasync)
psycopg2.OperationalError: could not connect to server: Connection refused
	Is the server running on host "localhost" (127.0.0.1) and accepting
	TCP/IP connections on port 5433?
could not connect to server: Cannot assign requested address
	Is the server running on host "localhost" (::1) and accepting
	TCP/IP connections on port 5433?


During handling of the above exception, another exception occurred:

Traceback (most recent call last):
  File "/home/airflow/.local/lib/python3.6/site-packages/airflow/models/taskinstance.py", line 1157, in _run_raw_task
    self._prepare_and_execute_task_with_callbacks(context, task)
  File "/home/airflow/.local/lib/python3.6/site-packages/airflow/models/taskinstance.py", line 1331, in _prepare_and_execute_task_with_callbacks
    result = self._execute_task(context, task_copy)
  File "/home/airflow/.local/lib/python3.6/site-packages/airflow/models/taskinstance.py", line 1361, in _execute_task
    result = task_copy.execute(context=context)
  File "/home/airflow/.local/lib/python3.6/site-packages/airflow/operators/python.py", line 150, in execute
    return_value = self.execute_callable()
  File "/home/airflow/.local/lib/python3.6/site-packages/airflow/operators/python.py", line 161, in execute_callable
    return self.python_callable(*self.op_args, **self.op_kwargs)
  File "/opt/airflow/dags/spotify-etl/spotify-etl.py", line 129, in insert_into_database
    conn = get_connection()
  File "/opt/airflow/dags/spotify-etl/spotify-etl.py", line 99, in get_connection
    raise Exception("Error connecting to database: {error}".format(error=error))
Exception: Error connecting to database: could not connect to server: Connection refused
	Is the server running on host "localhost" (127.0.0.1) and accepting
	TCP/IP connections on port 5433?
could not connect to server: Cannot assign requested address
	Is the server running on host "localhost" (::1) and accepting
	TCP/IP connections on port 5433?

[2021-08-16 15:50:43,695] {taskinstance.py:1551} INFO - Marking task as FAILED. dag_id=spotify-etl, task_id=insert_into_database, execution_date=20210816T155040, start_date=20210816T155043, end_date=20210816T155043
[2021-08-16 15:50:43,746] {local_task_job.py:149} INFO - Task exited with return code 1
