[2021-08-16 17:00:01,594] {taskinstance.py:896} INFO - Dependencies all met for <TaskInstance: spotify-etl.get_recently_played_songs_data 2021-08-16T16:00:00+00:00 [queued]>
[2021-08-16 17:00:01,605] {taskinstance.py:896} INFO - Dependencies all met for <TaskInstance: spotify-etl.get_recently_played_songs_data 2021-08-16T16:00:00+00:00 [queued]>
[2021-08-16 17:00:01,606] {taskinstance.py:1087} INFO - 
--------------------------------------------------------------------------------
[2021-08-16 17:00:01,606] {taskinstance.py:1088} INFO - Starting attempt 1 of 1
[2021-08-16 17:00:01,606] {taskinstance.py:1089} INFO - 
--------------------------------------------------------------------------------
[2021-08-16 17:00:01,620] {taskinstance.py:1107} INFO - Executing <Task(PythonOperator): get_recently_played_songs_data> on 2021-08-16T16:00:00+00:00
[2021-08-16 17:00:01,625] {standard_task_runner.py:52} INFO - Started process 5033 to run task
[2021-08-16 17:00:01,631] {standard_task_runner.py:76} INFO - Running: ['***', 'tasks', 'run', 'spotify-etl', 'get_recently_played_songs_data', '2021-08-16T16:00:00+00:00', '--job-id', '50', '--pool', 'default_pool', '--raw', '--subdir', 'DAGS_FOLDER/spotify-etl/spotify-etl.py', '--cfg-path', '/tmp/tmpunkwxi5q', '--error-file', '/tmp/tmpc1iqepoe']
[2021-08-16 17:00:01,632] {standard_task_runner.py:77} INFO - Job 50: Subtask get_recently_played_songs_data
[2021-08-16 17:00:01,693] {logging_mixin.py:104} INFO - Running <TaskInstance: spotify-etl.get_recently_played_songs_data 2021-08-16T16:00:00+00:00 [running]> on host 4095d62d00ed
[2021-08-16 17:00:01,754] {taskinstance.py:1302} INFO - Exporting the following env vars:
AIRFLOW_CTX_DAG_OWNER=***
AIRFLOW_CTX_DAG_ID=spotify-etl
AIRFLOW_CTX_TASK_ID=get_recently_played_songs_data
AIRFLOW_CTX_EXECUTION_DATE=2021-08-16T16:00:00+00:00
AIRFLOW_CTX_DAG_RUN_ID=scheduled__2021-08-16T16:00:00+00:00
[2021-08-16 17:00:02,041] {taskinstance.py:1501} ERROR - Task failed with exception
Traceback (most recent call last):
  File "/opt/airflow/dags/spotify-etl/spotify-etl.py", line 34, in get_recently_played_songs
    for song in data['items']:
KeyError: 'items'

During handling of the above exception, another exception occurred:

Traceback (most recent call last):
  File "/home/airflow/.local/lib/python3.6/site-packages/airflow/models/taskinstance.py", line 1157, in _run_raw_task
    self._prepare_and_execute_task_with_callbacks(context, task)
  File "/home/airflow/.local/lib/python3.6/site-packages/airflow/models/taskinstance.py", line 1331, in _prepare_and_execute_task_with_callbacks
    result = self._execute_task(context, task_copy)
  File "/home/airflow/.local/lib/python3.6/site-packages/airflow/models/taskinstance.py", line 1361, in _execute_task
    result = task_copy.execute(context=context)
  File "/home/airflow/.local/lib/python3.6/site-packages/airflow/operators/python.py", line 150, in execute
    return_value = self.execute_callable()
  File "/home/airflow/.local/lib/python3.6/site-packages/airflow/operators/python.py", line 161, in execute_callable
    return self.python_callable(*self.op_args, **self.op_kwargs)
  File "/opt/airflow/dags/spotify-etl/spotify-etl.py", line 49, in get_recently_played_songs
    raise Exception("Error consulting spotify API: {error}".format(error=error))
Exception: Error consulting spotify API: 'items'
[2021-08-16 17:00:02,052] {taskinstance.py:1551} INFO - Marking task as FAILED. dag_id=spotify-etl, task_id=get_recently_played_songs_data, execution_date=20210816T160000, start_date=20210816T170001, end_date=20210816T170002
[2021-08-16 17:00:02,084] {local_task_job.py:149} INFO - Task exited with return code 1
