[2021-08-16 14:55:10,727] {taskinstance.py:896} INFO - Dependencies all met for <TaskInstance: spotify-etl.get_recently_played_songs_data 2021-08-16T14:55:07.710166+00:00 [queued]>
[2021-08-16 14:55:10,742] {taskinstance.py:896} INFO - Dependencies all met for <TaskInstance: spotify-etl.get_recently_played_songs_data 2021-08-16T14:55:07.710166+00:00 [queued]>
[2021-08-16 14:55:10,742] {taskinstance.py:1087} INFO - 
--------------------------------------------------------------------------------
[2021-08-16 14:55:10,743] {taskinstance.py:1088} INFO - Starting attempt 1 of 1
[2021-08-16 14:55:10,743] {taskinstance.py:1089} INFO - 
--------------------------------------------------------------------------------
[2021-08-16 14:55:10,763] {taskinstance.py:1107} INFO - Executing <Task(PythonOperator): get_recently_played_songs_data> on 2021-08-16T14:55:07.710166+00:00
[2021-08-16 14:55:10,769] {standard_task_runner.py:52} INFO - Started process 178 to run task
[2021-08-16 14:55:10,774] {standard_task_runner.py:76} INFO - Running: ['***', 'tasks', 'run', 'spotify-etl', 'get_recently_played_songs_data', '2021-08-16T14:55:07.710166+00:00', '--job-id', '10', '--pool', 'default_pool', '--raw', '--subdir', 'DAGS_FOLDER/spotify-full-etl.py', '--cfg-path', '/tmp/tmp8nh8zdpo', '--error-file', '/tmp/tmp_xubf23j']
[2021-08-16 14:55:10,775] {standard_task_runner.py:77} INFO - Job 10: Subtask get_recently_played_songs_data
[2021-08-16 14:55:10,831] {logging_mixin.py:104} INFO - Running <TaskInstance: spotify-etl.get_recently_played_songs_data 2021-08-16T14:55:07.710166+00:00 [running]> on host 4095d62d00ed
[2021-08-16 14:55:10,888] {taskinstance.py:1302} INFO - Exporting the following env vars:
AIRFLOW_CTX_DAG_OWNER=***
AIRFLOW_CTX_DAG_ID=spotify-etl
AIRFLOW_CTX_TASK_ID=get_recently_played_songs_data
AIRFLOW_CTX_EXECUTION_DATE=2021-08-16T14:55:07.710166+00:00
AIRFLOW_CTX_DAG_RUN_ID=manual__2021-08-16T14:55:07.710166+00:00
[2021-08-16 14:55:10,889] {taskinstance.py:1501} ERROR - Task failed with exception
Traceback (most recent call last):
  File "/opt/airflow/dags/spotify-full-etl.py", line 25, in get_recently_played_songs
    today =  datetime.datetime.now()
AttributeError: type object 'datetime.datetime' has no attribute 'datetime'

During handling of the above exception, another exception occurred:

Traceback (most recent call last):
  File "/home/airflow/.local/lib/python3.6/site-packages/airflow/models/taskinstance.py", line 1157, in _run_raw_task
    self._prepare_and_execute_task_with_callbacks(context, task)
  File "/home/airflow/.local/lib/python3.6/site-packages/airflow/models/taskinstance.py", line 1331, in _prepare_and_execute_task_with_callbacks
    result = self._execute_task(context, task_copy)
  File "/home/airflow/.local/lib/python3.6/site-packages/airflow/models/taskinstance.py", line 1361, in _execute_task
    result = task_copy.execute(context=context)
  File "/home/airflow/.local/lib/python3.6/site-packages/airflow/operators/python.py", line 150, in execute
    return_value = self.execute_callable()
  File "/home/airflow/.local/lib/python3.6/site-packages/airflow/operators/python.py", line 161, in execute_callable
    return self.python_callable(*self.op_args, **self.op_kwargs)
  File "/opt/airflow/dags/spotify-full-etl.py", line 50, in get_recently_played_songs
    raise Exception("Error consulting spotify API: {error}".format(error=error))
Exception: Error consulting spotify API: type object 'datetime.datetime' has no attribute 'datetime'
[2021-08-16 14:55:10,894] {taskinstance.py:1551} INFO - Marking task as FAILED. dag_id=spotify-etl, task_id=get_recently_played_songs_data, execution_date=20210816T145507, start_date=20210816T145510, end_date=20210816T145510
[2021-08-16 14:55:10,945] {local_task_job.py:149} INFO - Task exited with return code 1
